<?xml version="1.0" encoding="UTF-8"?>
<testng-results skipped="0" failed="1" ignored="0" total="1" passed="0">
  <reporter-output>
  </reporter-output>
  <suite name="Default suite" duration-ms="52638" started-at="2017-10-04T21:34:54Z" finished-at="2017-10-04T21:35:46Z">
    <groups>
    </groups>
    <test name="Default test" duration-ms="52638" started-at="2017-10-04T21:34:54Z" finished-at="2017-10-04T21:35:46Z">
      <class name="tests.SignInUpTest">
        <test-method status="PASS" signature="setUp()[pri:0, instance:tests.SignInUpTest@42dafa95]" name="setUp" is-config="true" duration-ms="7242" started-at="2017-10-04T17:34:54Z" finished-at="2017-10-04T17:35:01Z">
          <reporter-output>
          </reporter-output>
        </test-method> <!-- setUp -->
        <test-method status="FAIL" signature="signUpWithExistingIdTest(java.lang.String, java.lang.String)[pri:0, instance:tests.SignInUpTest@42dafa95]" name="signUpWithExistingIdTest" duration-ms="45239" started-at="2017-10-04T17:35:01Z" description="Sign Out (Functional), &#039;Signing out from application.&#039;" data-provider="verifiedCredentials" finished-at="2017-10-04T17:35:46Z">
          <params>
            <param index="0">
              <value>
                <![CDATA[123lbtester@gmail.com]]>
              </value>
            </param>
            <param index="1">
              <value>
                <![CDATA[loadboard]]>
              </value>
            </param>
          </params>
          <exception class="java.lang.AssertionError">
            <message>
              <![CDATA[The following asserts failed:
	Can not check password error message as it was not found.]]>
            </message>
            <full-stacktrace>
              <![CDATA[java.lang.AssertionError: The following asserts failed:
	Can not check password error message as it was not found.
	at reporting.CustomAssert.assertAll(CustomAssert.java:47)
	at tests.SignInUpTest.signUpWithExistingIdTest(SignInUpTest.java:220)
	at sun.reflect.NativeMethodAccessorImpl.invoke0(Native Method)
	at sun.reflect.NativeMethodAccessorImpl.invoke(Unknown Source)
	at sun.reflect.DelegatingMethodAccessorImpl.invoke(Unknown Source)
	at java.lang.reflect.Method.invoke(Unknown Source)
	at org.testng.internal.MethodInvocationHelper.invokeMethod(MethodInvocationHelper.java:108)
	at org.testng.internal.Invoker.invokeMethod(Invoker.java:661)
	at org.testng.internal.Invoker.invokeTestMethod(Invoker.java:869)
	at org.testng.internal.Invoker.invokeTestMethods(Invoker.java:1193)
	at org.testng.internal.TestMethodWorker.invokeTestMethods(TestMethodWorker.java:126)
	at org.testng.internal.TestMethodWorker.run(TestMethodWorker.java:109)
	at org.testng.TestRunner.privateRun(TestRunner.java:744)
	at org.testng.TestRunner.run(TestRunner.java:602)
	at org.testng.SuiteRunner.runTest(SuiteRunner.java:380)
	at org.testng.SuiteRunner.runSequentially(SuiteRunner.java:375)
	at org.testng.SuiteRunner.privateRun(SuiteRunner.java:340)
	at org.testng.SuiteRunner.run(SuiteRunner.java:289)
	at org.testng.SuiteRunnerWorker.runSuite(SuiteRunnerWorker.java:52)
	at org.testng.SuiteRunnerWorker.run(SuiteRunnerWorker.java:86)
	at org.testng.TestNG.runSuitesSequentially(TestNG.java:1301)
	at org.testng.TestNG.runSuitesLocally(TestNG.java:1226)
	at org.testng.TestNG.runSuites(TestNG.java:1144)
	at org.testng.TestNG.run(TestNG.java:1115)
	at org.testng.remote.AbstractRemoteTestNG.run(AbstractRemoteTestNG.java:114)
	at org.testng.remote.RemoteTestNG.initAndRun(RemoteTestNG.java:251)
	at org.testng.remote.RemoteTestNG.main(RemoteTestNG.java:77)
]]>
            </full-stacktrace>
          </exception> <!-- java.lang.AssertionError -->
          <reporter-output>
          </reporter-output>
        </test-method> <!-- signUpWithExistingIdTest -->
      </class> <!-- tests.SignInUpTest -->
    </test> <!-- Default test -->
  </suite> <!-- Default suite -->
</testng-results>
